Workbook
Name Slicer_Department: #N/A
Name Slicer_Month: #N/A
Name Slicer_Sales_Channel: #N/A

Sheet Dashboard
B6: Key Performance Indicators
B21: Key Insight: Revenue beat budget by $1.4M, but operating profit missed budget by $0.9M. Wholesale drove the strongest operating profit.
U22: Note: Slicers apply to charts based on the Analysis sheet

Sheet Raw Data
A1: Month | B1: Sales Channel | C1: Department | D1: Units Sold | E1: Average Selling Price | F1: Revenue | G1: Cost of Goods Sold | H1: Marketing Expense | I1: Payroll Expense | J1: Allocated Rent Expense | K1: Other Expense | N1: Note: These formulas show how the synthetic dataset was generated. Final values were pasted as "Values Only" so the data does not recalculate.
A2: Jan | B2: Online | C2: Furniture | D2: 1984 | E2: 100 | F2: 198400 | G2: 136558.72 | H2: 20336 | I2: 11768 | J2: 1365 | K2: 11606.4 | N2: Column Name | O2: Business Logic | P2: Formula Used
A3: Jan | B3: Online | C3: Home Decor | D3: 1117 | E3: 70 | F3: 78190 | G3: 44474.472 | H3: 6591.417 | I3: 11455 | J3: 2935 | K3: 1806.189 | N3: Units Sold | O3: Units sold depends on sales channel | P3: =IFS([@[Sales Channel]]="Online",RANDBETWEEN(600,2200),[@[Sales Channel]]="Retail",RANDBETWEEN(300,1400),[@[Sales Channel]]="Wholesale",RANDBETWEEN(1000,3500))
A4: Jan | B4: Online | C4: Kitchen | D4: 1282 | E4: 71 | F4: 91022 | G4: 51463.839 | H4: 6844.8544 | I4: 7845 | J4: 1830 | K4: 2730.66 | N4: Average Selling Price | O4: Prices are different based on the department | P4: =IFS([@Department]="Furniture",RANDBETWEEN(80,250),[@Department]="Home Decor",RANDBETWEEN(20,75),[@Department]="Kitchen",RANDBETWEEN(25,120),[@Department]="Appliances",RANDBETWEEN(150,600),[@Department]="Seasonal",RANDBETWEEN(15,90))
A5: Jan | B5: Online | C5: Appliances | D5: 2088 | E5: 415 | F5: 866520 | G5: 582214.79 | H5: 64815.696 | I5: 8127 | J5: 3628 | K5: 17677.008 | N5: Revenue | O5: Units sold × average selling price | P5: =[@[Units Sold]]*[@[Average Selling Price]] | T5: .
A6: Jan | B6: Online | C6: Seasonal | D6: 1859 | E6: 36 | F6: 66924 | G6: 33348.229 | H6: 4611.0636 | I6: 5630 | J6: 3054 | K6: 3707.5896 | N6: Cost of Goods Sold | O6: COGS is estimated as a percentage of revenue | P6: =[@Revenue]*IFS([@Department]="Furniture",RANDBETWEEN(5800,7200)/10000,[@Department]="Home Decor",RANDBETWEEN(4500,6000)/10000,[@Department]="Kitchen",RANDBETWEEN(5000,6500)/10000,[@Department]="Appliances", RANDBETWEEN(6200,7600)/10000,[@Department]="Seasonal",RANDBETWEEN(4800,6800)/10000)
A7: Jan | B7: Retail | C7: Furniture | D7: 1321 | E7: 226 | F7: 298546 | G7: 214803.85 | H7: 18718.834 | I7: 17326 | J7: 15411 | K7: 13882.389 | N7: Marketing Expense | O7: Marketing is higher for Online sales | P7: =[@Revenue]*IFS([@[Sales Channel]]="Online", RANDBETWEEN(600,1200)/10000,[@[Sales Channel]]="Retail",RANDBETWEEN(300,700)/10000,[@[Sales Channel]]="Wholesale",RANDBETWEEN(200,500)/10000)
A8: Jan | B8: Retail | C8: Home Decor | D8: 703 | E8: 61 | F8: 42883 | G8: 23426.983 | H8: 2988.9451 | I8: 9272 | J8: 8452 | K8: 1904.0052 | N8: Payroll Expense | O8: Payroll cost depends on sales channel | P8: =IFS([@[Sales Channel]]="Online",RANDBETWEEN(4000,12000),[@[Sales Channel]]="Retail",RANDBETWEEN(8000,20000),[@[Sales Channel]]="Wholesale",RANDBETWEEN(5000,14000))
A9: Jan | B9: Retail | C9: Kitchen | D9: 1041 | E9: 38 | F9: 39558 | G9: 21863.707 | H9: 2365.5684 | I9: 8564 | J9: 15680 | K9: 2353.701 | N9: Allocated Rent Expense | O9: Retail usually has higher rent costs | P9: =IFS([@[Sales Channel]]="Online",RANDBETWEEN(1000,4000),[@[Sales Channel]]="Retail",RANDBETWEEN(6000,16000),[@[Sales Channel]]="Wholesale",RANDBETWEEN(2000,7000))
A10: Jan | B10: Retail | C10: Appliances | D10: 852 | E10: 192 | F10: 163584 | G10: 103286.94 | H10: 5676.3648 | I10: 14006 | J10: 12582 | K10: 6232.5504 | N10: Other Expense | O10: Other expenses are estimated as a small percentage of revenue | P10: =[@Revenue]*RANDBETWEEN(200,600)/10000
A11: Jan | B11: Retail | C11: Seasonal | D11: 1164 | E11: 27 | F11: 31428 | G11: 19557.644 | H11: 1382.832 | I11: 19539 | J11: 14355 | K11: 854.8416
A12: Jan | B12: Wholesale | C12: Furniture | D12: 3419 | E12: 147 | F12: 502593 | G12: 342416.61 | H12: 12564.825 | I12: 5082 | J12: 3086 | K12: 16334.272
A13: Jan | B13: Wholesale | C13: Home Decor | D13: 3277 | E13: 25 | F13: 81925 | G13: 48827.3 | H13: 3539.16 | I13: 12480 | J13: 2328 | K13: 3309.77
A14: Jan | B14: Wholesale | C14: Kitchen | D14: 1625 | E14: 32 | F14: 52000 | G14: 32650.8 | H14: 2225.6 | I14: 11417 | J14: 6582 | K14: 3047.2
A15: Jan | B15: Wholesale | C15: Appliances | D15: 2999 | E15: 315 | F15: 944685 | G15: 670820.82 | H15: 34197.597 | I15: 8563 | J15: 2083 | K15: 32213.758
A16: Jan | B16: Wholesale | C16: Seasonal | D16: 1345 | E16: 18 | F16: 24210 | G16: 14797.152 | H16: 1070.082 | I16: 5579 | J16: 5098 | K16: 1147.554
A17: Feb | B17: Online | C17: Furniture | D17: 2147 | E17: 85 | F17: 182495 | G17: 130757.67 | H17: 20822.679 | I17: 4278 | J17: 3905 | K17: 5073.361
A18: Feb | B18: Online | C18: Home Decor | D18: 1015 | E18: 41 | F18: 41615 | G18: 24061.793 | H18: 3578.89 | I18: 9449 | J18: 3387 | K18: 1510.6245
A19: Feb | B19: Online | C19: Kitchen | D19: 1693 | E19: 36 | F19: 60948 | G19: 36733.36 | H19: 5521.8888 | I19: 10784 | J19: 2065 | K19: 1999.0944
A20: Feb | B20: Online | C20: Appliances | D20: 1324 | E20: 213 | F20: 282012 | G20: 194475.48 | H20: 32262.173 | I20: 11190 | J20: 1630 | K20: 8855.1768
A21: Feb | B21: Online | C21: Seasonal | D21: 1410 | E21: 87 | F21: 122670 | G21: 68474.394 | H21: 8218.89 | I21: 10173 | J21: 2566 | K21: 3557.43
A22: Feb | B22: Retail | C22: Furniture | D22: 503 | E22: 88 | F22: 44264 | G22: 27045.304 | H22: 1894.4992 | I22: 14733 | J22: 9312 | K22: 2208.7736
... A181: Dec | B181: Wholesale | C181: Seasonal | D181: 2664 | E181: 74 | F181: 197136 | G181: 133401.93 | H181: 9383.6736 | I181: 9877 | J181: 6614 | K181: 10645.344

Sheet Budget
A1: Month | B1: Budget Revenue | C1: Budget COGS | D1: Budget Operating Expenses | E1: Budget Operating Profit | H1: Note: These formulas show how the budget values were generated. Final values were pasted as “Values Only” so the budget does not recalculate.
A2: Jan | B2: 3377297.5 | C2: 1937555.6 | D2: 737939.5 | E2: 701802.41 | H2: Budget Field | I2: Formula Used
A3: Feb | B3: 3703256.8 | C3: 2136038.5 | D3: 808791.29 | E3: 758427 | H3: Budget Revenue | I3: =SUMIFS(FinancialData[Revenue],FinancialData[Month],[@Month]) * RANDBETWEEN(9500,9800)/10000
A4: Mar | B4: 1905033.6 | C4: 1040338.8 | D4: 505786.42 | E4: 358908.33 | H4: Budget COGS | I4: =[@[Budget Revenue]]*RANDBETWEEN(5000,6000)/10000
A5: Apr | B5: 3092009.3 | C5: 1571049.9 | D5: 762489.5 | E5: 758469.89 | H5: Budget Operating Expenses | I5: =[@[Budget Revenue]]*RANDBETWEEN(2000,3000)/10000
A6: May | B6: 3951363.2 | C6: 2307596.1 | D6: 832947.37 | E6: 810819.73 | H6: Budget Operating Profit | I6: =[@[Budget Revenue]]-[@[Budget COGS]]-[@[Budget Operating Expenses]]
A7: Jun | B7: 2248435.7 | C7: 1347487.5 | D7: 608426.71 | E7: 292521.49
A8: Jul | B8: 3425051.8 | C8: 1982420 | D8: 873730.72 | E8: 568901.11
A9: Aug | B9: 2801452.9 | C9: 1588423.8 | D9: 667586.23 | E9: 545442.89
A10: Sep | B10: 3604429.3 | C10: 1964774.4 | D10: 782161.16 | E10: 857493.74
A11: Oct | B11: 3232258.3 | C11: 1870831.1 | D11: 799660.71 | E11: 561766.49
A12: Nov | B12: 3122564.6 | C12: 1734896.9 | D12: 755660.63 | E12: 632007.07
A13: Dec | B13: 4020334.6 | C13: 2067256.1 | D13: 977343.34 | E13: 975735.21

Sheet Analysis
A1: Month | B1: Sales Channel | C1: Department | D1: Units Sold | E1: Average Selling Price | F1: Revenue | G1: Cost of Goods Sold | H1: Marketing Expense | I1: Payroll Expense | J1: Allocated Rent Expense | K1: Other Expense | L1: Total Operating Expenses | M1: Gross Profit | N1: Operating Profit | O1: Gross Margin | P1: Operating Margin | Q1: Revenue Per Unit | R1: COGS Per Unit | S1: Expense Ratio | T1: Profit Status
A2: Jan | B2: Online | C2: Furniture | D2: 1984 | E2: 100 | F2: 198400 | G2: 136558.72 | H2: 20336 | I2: 11768 | J2: 1365 | K2: 11606.4 | L2: =SUM(FinancialAnalysis[[#This Row],[Marketing Expense]:[Other Expense]]) -> 45075.4 | M2: =FinancialAnalysis[[#This Row],[Revenue]]-FinancialAnalysis[[#This Row],[Cost of Goods Sold]] -> 61841.28 | N2: =FinancialAnalysis[[#This Row],[Gross Profit]]-FinancialAnalysis[[#This Row],[Total Operating Expenses]] -> 16765.88 | O2: =FinancialAnalysis[[#This Row],[Gross Profit]]/FinancialAnalysis[[#This Row],[Revenue]] -> 0.3117 | P2: =FinancialAnalysis[[#This Row],[Operating Profit]]/FinancialAnalysis[[#This Row],[Revenue]] -> 0.084505444 | Q2: =FinancialAnalysis[[#This Row],[Revenue]]/FinancialAnalysis[[#This Row],[Units Sold]] -> 100 | R2: =FinancialAnalysis[[#This Row],[Cost of Goods Sold]]/FinancialAnalysis[[#This Row],[Units Sold]] -> 68.83 | S2: =FinancialAnalysis[[#This Row],[Total Operating Expenses]]/FinancialAnalysis[[#This Row],[Revenue]] -> 0.22719456 | T2: =IF(FinancialAnalysis[[#This Row],[Operating Profit]]>0,"Profitable","Not Profitable") -> Profitable
A3: Jan | B3: Online | C3: Home Decor | D3: 1117 | E3: 70 | F3: 78190 | G3: 44474.472 | H3: 6591.417 | I3: 11455 | J3: 2935 | K3: 1806.189 | L3: =SUM(FinancialAnalysis[[#This Row],[Marketing Expense]:[Other Expense]]) -> 22787.606 | M3: =FinancialAnalysis[[#This Row],[Revenue]]-FinancialAnalysis[[#This Row],[Cost of Goods Sold]] -> 33715.528 | N3: =FinancialAnalysis[[#This Row],[Gross Profit]]-FinancialAnalysis[[#This Row],[Total Operating Expenses]] -> 10927.922 | O3: =FinancialAnalysis[[#This Row],[Gross Profit]]/FinancialAnalysis[[#This Row],[Revenue]] -> 0.4312 | P3: =FinancialAnalysis[[#This Row],[Operating Profit]]/FinancialAnalysis[[#This Row],[Revenue]] -> 0.13976112 | Q3: =FinancialAnalysis[[#This Row],[Revenue]]/FinancialAnalysis[[#This Row],[Units Sold]] -> 70 | R3: =FinancialAnalysis[[#This Row],[Cost of Goods Sold]]/FinancialAnalysis[[#This Row],[Units Sold]] -> 39.816 | S3: =FinancialAnalysis[[#This Row],[Total Operating Expenses]]/FinancialAnalysis[[#This Row],[Revenue]] -> 0.29143888 | T3: =IF(FinancialAnalysis[[#This Row],[Operating Profit]]>0,"Profitable","Not Profitable") -> Profitable
A4: Jan | B4: Online | C4: Kitchen | D4: 1282 | E4: 71 | F4: 91022 | G4: 51463.839 | H4: 6844.8544 | I4: 7845 | J4: 1830 | K4: 2730.66 | L4: =SUM(FinancialAnalysis[[#This Row],[Marketing Expense]:[Other Expense]]) -> 19250.514 | M4: =FinancialAnalysis[[#This Row],[Revenue]]-FinancialAnalysis[[#This Row],[Cost of Goods Sold]] -> 39558.161 | N4: =FinancialAnalysis[[#This Row],[Gross Profit]]-FinancialAnalysis[[#This Row],[Total Operating Expenses]] -> 20307.647 | O4: =FinancialAnalysis[[#This Row],[Gross Profit]]/FinancialAnalysis[[#This Row],[Revenue]] -> 0.4346 | P4: =FinancialAnalysis[[#This Row],[Operating Profit]]/FinancialAnalysis[[#This Row],[Revenue]] -> 0.22310702 | Q4: =FinancialAnalysis[[#This Row],[Revenue]]/FinancialAnalysis[[#This Row],[Units Sold]] -> 71 | R4: =FinancialAnalysis[[#This Row],[Cost of Goods Sold]]/FinancialAnalysis[[#This Row],[Units Sold]] -> 40.1434 | S4: =FinancialAnalysis[[#This Row],[Total Operating Expenses]]/FinancialAnalysis[[#This Row],[Revenue]] -> 0.21149298 | T4: =IF(FinancialAnalysis[[#This Row],[Operating Profit]]>0,"Profitable","Not Profitable") -> Profitable
A5: Jan | B5: Online | C5: Appliances | D5: 2088 | E5: 415 | F5: 866520 | G5: 582214.79 | H5: 64815.696 | I5: 8127 | J5: 3628 | K5: 17677.008 | L5: =SUM(FinancialAnalysis[[#This Row],[Marketing Expense]:[Other Expense]]) -> 94247.704 | M5: =FinancialAnalysis[[#This Row],[Revenue]]-FinancialAnalysis[[#This Row],[Cost of Goods Sold]] -> 284305.21 | N5: =FinancialAnalysis[[#This Row],[Gross Profit]]-FinancialAnalysis[[#This Row],[Total Operating Expenses]] -> 190057.51 | O5: =FinancialAnalysis[[#This Row],[Gross Profit]]/FinancialAnalysis[[#This Row],[Revenue]] -> 0.3281 | P5: =FinancialAnalysis[[#This Row],[Operating Profit]]/FinancialAnalysis[[#This Row],[Revenue]] -> 0.21933424 | Q5: =FinancialAnalysis[[#This Row],[Revenue]]/FinancialAnalysis[[#This Row],[Units Sold]] -> 415 | R5: =FinancialAnalysis[[#This Row],[Cost of Goods Sold]]/FinancialAnalysis[[#This Row],[Units Sold]] -> 278.8385 | S5: =FinancialAnalysis[[#This Row],[Total Operating Expenses]]/FinancialAnalysis[[#This Row],[Revenue]] -> 0.10876576 | T5: =IF(FinancialAnalysis[[#This Row],[Operating Profit]]>0,"Profitable","Not Profitable") -> Profitable
A6: Jan | B6: Online | C6: Seasonal | D6: 1859 | E6: 36 | F6: 66924 | G6: 33348.229 | H6: 4611.0636 | I6: 5630 | J6: 3054 | K6: 3707.5896 | L6: =SUM(FinancialAnalysis[[#This Row],[Marketing Expense]:[Other Expense]]) -> 17002.653 | M6: =FinancialAnalysis[[#This Row],[Revenue]]-FinancialAnalysis[[#This Row],[Cost of Goods Sold]] -> 33575.771 | N6: =FinancialAnalysis[[#This Row],[Gross Profit]]-FinancialAnalysis[[#This Row],[Total Operating Expenses]] -> 16573.118 | O6: =FinancialAnalysis[[#This Row],[Gross Profit]]/FinancialAnalysis[[#This Row],[Revenue]] -> 0.5017 | P6: =FinancialAnalysis[[#This Row],[Operating Profit]]/FinancialAnalysis[[#This Row],[Revenue]] -> 0.24764087 | Q6: =FinancialAnalysis[[#This Row],[Revenue]]/FinancialAnalysis[[#This Row],[Units Sold]] -> 36 | R6: =FinancialAnalysis[[#This Row],[Cost of Goods Sold]]/FinancialAnalysis[[#This Row],[Units Sold]] -> 17.9388 | S6: =FinancialAnalysis[[#This Row],[Total Operating Expenses]]/FinancialAnalysis[[#This Row],[Revenue]] -> 0.25405913 | T6: =IF(FinancialAnalysis[[#This Row],[Operating Profit]]>0,"Profitable","Not Profitable") -> Profitable
A7: Jan | B7: Retail | C7: Furniture | D7: 1321 | E7: 226 | F7: 298546 | G7: 214803.85 | H7: 18718.834 | I7: 17326 | J7: 15411 | K7: 13882.389 | L7: =SUM(FinancialAnalysis[[#This Row],[Marketing Expense]:[Other Expense]]) -> 65338.223 | M7: =FinancialAnalysis[[#This Row],[Revenue]]-FinancialAnalysis[[#This Row],[Cost of Goods Sold]] -> 83742.153 | N7: =FinancialAnalysis[[#This Row],[Gross Profit]]-FinancialAnalysis[[#This Row],[Total Operating Expenses]] -> 18403.93 | O7: =FinancialAnalysis[[#This Row],[Gross Profit]]/FinancialAnalysis[[#This Row],[Revenue]] -> 0.2805 | P7: =FinancialAnalysis[[#This Row],[Operating Profit]]/FinancialAnalysis[[#This Row],[Revenue]] -> 0.061645206 | Q7: =FinancialAnalysis[[#This Row],[Revenue]]/FinancialAnalysis[[#This Row],[Units Sold]] -> 226 | R7: =FinancialAnalysis[[#This Row],[Cost of Goods Sold]]/FinancialAnalysis[[#This Row],[Units Sold]] -> 162.607 | S7: =FinancialAnalysis[[#This Row],[Total Operating Expenses]]/FinancialAnalysis[[#This Row],[Revenue]] -> 0.21885479 | T7: =IF(FinancialAnalysis[[#This Row],[Operating Profit]]>0,"Profitable","Not Profitable") -> Profitable
A8: Jan | B8: Retail | C8: Home Decor | D8: 703 | E8: 61 | F8: 42883 | G8: 23426.983 | H8: 2988.9451 | I8: 9272 | J8: 8452 | K8: 1904.0052 | L8: =SUM(FinancialAnalysis[[#This Row],[Marketing Expense]:[Other Expense]]) -> 22616.95 | M8: =FinancialAnalysis[[#This Row],[Revenue]]-FinancialAnalysis[[#This Row],[Cost of Goods Sold]] -> 19456.017 | N8: =FinancialAnalysis[[#This Row],[Gross Profit]]-FinancialAnalysis[[#This Row],[Total Operating Expenses]] -> -3160.9332 | O8: =FinancialAnalysis[[#This Row],[Gross Profit]]/FinancialAnalysis[[#This Row],[Revenue]] -> 0.4537 | P8: =FinancialAnalysis[[#This Row],[Operating Profit]]/FinancialAnalysis[[#This Row],[Revenue]] -> -0.073710636 | Q8: =FinancialAnalysis[[#This Row],[Revenue]]/FinancialAnalysis[[#This Row],[Units Sold]] -> 61 | R8: =FinancialAnalysis[[#This Row],[Cost of Goods Sold]]/FinancialAnalysis[[#This Row],[Units Sold]] -> 33.3243 | S8: =FinancialAnalysis[[#This Row],[Total Operating Expenses]]/FinancialAnalysis[[#This Row],[Revenue]] -> 0.52741064 | T8: =IF(FinancialAnalysis[[#This Row],[Operating Profit]]>0,"Profitable","Not Profitable") -> Not Profitable
A9: Jan | B9: Retail | C9: Kitchen | D9: 1041 | E9: 38 | F9: 39558 | G9: 21863.707 | H9: 2365.5684 | I9: 8564 | J9: 15680 | K9: 2353.701 | L9: =SUM(FinancialAnalysis[[#This Row],[Marketing Expense]:[Other Expense]]) -> 28963.269 | M9: =FinancialAnalysis[[#This Row],[Revenue]]-FinancialAnalysis[[#This Row],[Cost of Goods Sold]] -> 17694.293 | N9: =FinancialAnalysis[[#This Row],[Gross Profit]]-FinancialAnalysis[[#This Row],[Total Operating Expenses]] -> -11268.976 | O9: =FinancialAnalysis[[#This Row],[Gross Profit]]/FinancialAnalysis[[#This Row],[Revenue]] -> 0.4473 | P9: =FinancialAnalysis[[#This Row],[Operating Profit]]/FinancialAnalysis[[#This Row],[Revenue]] -> -0.28487224 | Q9: =FinancialAnalysis[[#This Row],[Revenue]]/FinancialAnalysis[[#This Row],[Units Sold]] -> 38 | R9: =FinancialAnalysis[[#This Row],[Cost of Goods Sold]]/FinancialAnalysis[[#This Row],[Units Sold]] -> 21.0026 | S9: =FinancialAnalysis[[#This Row],[Total Operating Expenses]]/FinancialAnalysis[[#This Row],[Revenue]] -> 0.73217224 | T9: =IF(FinancialAnalysis[[#This Row],[Operating Profit]]>0,"Profitable","Not Profitable") -> Not Profitable
A10: Jan | B10: Retail | C10: Appliances | D10: 852 | E10: 192 | F10: 163584 | G10: 103286.94 | H10: 5676.3648 | I10: 14006 | J10: 12582 | K10: 6232.5504 | L10: =SUM(FinancialAnalysis[[#This Row],[Marketing Expense]:[Other Expense]]) -> 38496.915 | M10: =FinancialAnalysis[[#This Row],[Revenue]]-FinancialAnalysis[[#This Row],[Cost of Goods Sold]] -> 60297.062 | N10: =FinancialAnalysis[[#This Row],[Gross Profit]]-FinancialAnalysis[[#This Row],[Total Operating Expenses]] -> 21800.147 | O10: =FinancialAnalysis[[#This Row],[Gross Profit]]/FinancialAnalysis[[#This Row],[Revenue]] -> 0.3686 | P10: =FinancialAnalysis[[#This Row],[Operating Profit]]/FinancialAnalysis[[#This Row],[Revenue]] -> 0.13326577 | Q10: =FinancialAnalysis[[#This Row],[Revenue]]/FinancialAnalysis[[#This Row],[Units Sold]] -> 192 | R10: =FinancialAnalysis[[#This Row],[Cost of Goods Sold]]/FinancialAnalysis[[#This Row],[Units Sold]] -> 121.2288 | S10: =FinancialAnalysis[[#This Row],[Total Operating Expenses]]/FinancialAnalysis[[#This Row],[Revenue]] -> 0.23533423 | T10: =IF(FinancialAnalysis[[#This Row],[Operating Profit]]>0,"Profitable","Not Profitable") -> Profitable
A11: Jan | B11: Retail | C11: Seasonal | D11: 1164 | E11: 27 | F11: 31428 | G11: 19557.644 | H11: 1382.832 | I11: 19539 | J11: 14355 | K11: 854.8416 | L11: =SUM(FinancialAnalysis[[#This Row],[Marketing Expense]:[Other Expense]]) -> 36131.674 | M11: =FinancialAnalysis[[#This Row],[Revenue]]-FinancialAnalysis[[#This Row],[Cost of Goods Sold]] -> 11870.356 | N11: =FinancialAnalysis[[#This Row],[Gross Profit]]-FinancialAnalysis[[#This Row],[Total Operating Expenses]] -> -24261.318 | O11: =FinancialAnalysis[[#This Row],[Gross Profit]]/FinancialAnalysis[[#This Row],[Revenue]] -> 0.3777 | P11: =FinancialAnalysis[[#This Row],[Operating Profit]]/FinancialAnalysis[[#This Row],[Revenue]] -> -0.77196506 | Q11: =FinancialAnalysis[[#This Row],[Revenue]]/FinancialAnalysis[[#This Row],[Units Sold]] -> 27 | R11: =FinancialAnalysis[[#This Row],[Cost of Goods Sold]]/FinancialAnalysis[[#This Row],[Units Sold]] -> 16.8021 | S11: =FinancialAnalysis[[#This Row],[Total Operating Expenses]]/FinancialAnalysis[[#This Row],[Revenue]] -> 1.1496651 | T11: =IF(FinancialAnalysis[[#This Row],[Operating Profit]]>0,"Profitable","Not Profitable") -> Not Profitable
A12: Jan | B12: Wholesale | C12: Furniture | D12: 3419 | E12: 147 | F12: 502593 | G12: 342416.61 | H12: 12564.825 | I12: 5082 | J12: 3086 | K12: 16334.272 | L12: =SUM(FinancialAnalysis[[#This Row],[Marketing Expense]:[Other Expense]]) -> 37067.098 | M12: =FinancialAnalysis[[#This Row],[Revenue]]-FinancialAnalysis[[#This Row],[Cost of Goods Sold]] -> 160176.39 | N12: =FinancialAnalysis[[#This Row],[Gross Profit]]-FinancialAnalysis[[#This Row],[Total Operating Expenses]] -> 123109.29 | O12: =FinancialAnalysis[[#This Row],[Gross Profit]]/FinancialAnalysis[[#This Row],[Revenue]] -> 0.3187 | P12: =FinancialAnalysis[[#This Row],[Operating Profit]]/FinancialAnalysis[[#This Row],[Revenue]] -> 0.24494828 | Q12: =FinancialAnalysis[[#This Row],[Revenue]]/FinancialAnalysis[[#This Row],[Units Sold]] -> 147 | R12: =FinancialAnalysis[[#This Row],[Cost of Goods Sold]]/FinancialAnalysis[[#This Row],[Units Sold]] -> 100.1511 | S12: =FinancialAnalysis[[#This Row],[Total Operating Expenses]]/FinancialAnalysis[[#This Row],[Revenue]] -> 0.073751719 | T12: =IF(FinancialAnalysis[[#This Row],[Operating Profit]]>0,"Profitable","Not Profitable") -> Profitable
A13: Jan | B13: Wholesale | C13: Home Decor | D13: 3277 | E13: 25 | F13: 81925 | G13: 48827.3 | H13: 3539.16 | I13: 12480 | J13: 2328 | K13: 3309.77 | L13: =SUM(FinancialAnalysis[[#This Row],[Marketing Expense]:[Other Expense]]) -> 21656.93 | M13: =FinancialAnalysis[[#This Row],[Revenue]]-FinancialAnalysis[[#This Row],[Cost of Goods Sold]] -> 33097.7 | N13: =FinancialAnalysis[[#This Row],[Gross Profit]]-FinancialAnalysis[[#This Row],[Total Operating Expenses]] -> 11440.77 | O13: =FinancialAnalysis[[#This Row],[Gross Profit]]/FinancialAnalysis[[#This Row],[Revenue]] -> 0.404 | P13: =FinancialAnalysis[[#This Row],[Operating Profit]]/FinancialAnalysis[[#This Row],[Revenue]] -> 0.13964931 | Q13: =FinancialAnalysis[[#This Row],[Revenue]]/FinancialAnalysis[[#This Row],[Units Sold]] -> 25 | R13: =FinancialAnalysis[[#This Row],[Cost of Goods Sold]]/FinancialAnalysis[[#This Row],[Units Sold]] -> 14.9 | S13: =FinancialAnalysis[[#This Row],[Total Operating Expenses]]/FinancialAnalysis[[#This Row],[Revenue]] -> 0.26435069 | T13: =IF(FinancialAnalysis[[#This Row],[Operating Profit]]>0,"Profitable","Not Profitable") -> Profitable
... A181: Dec | B181: Wholesale | C181: Seasonal | D181: 2664 | E181: 74 | F181: 197136 | G181: 133401.93 | H181: 9383.6736 | I181: 9877 | J181: 6614 | K181: 10645.344 | L181: =SUM(FinancialAnalysis[[#This Row],[Marketing Expense]:[Other Expense]]) -> 36520.018 | M181: =FinancialAnalysis[[#This Row],[Revenue]]-FinancialAnalysis[[#This Row],[Cost of Goods Sold]] -> 63734.069 | N181: =FinancialAnalysis[[#This Row],[Gross Profit]]-FinancialAnalysis[[#This Row],[Total Operating Expenses]] -> 27214.051 | O181: =FinancialAnalysis[[#This Row],[Gross Profit]]/FinancialAnalysis[[#This Row],[Revenue]] -> 0.3233 | P181: =FinancialAnalysis[[#This Row],[Operating Profit]]/FinancialAnalysis[[#This Row],[Revenue]] -> 0.13804709 | Q181: =FinancialAnalysis[[#This Row],[Revenue]]/FinancialAnalysis[[#This Row],[Units Sold]] -> 74 | R181: =FinancialAnalysis[[#This Row],[Cost of Goods Sold]]/FinancialAnalysis[[#This Row],[Units Sold]] -> 50.0758 | S181: =FinancialAnalysis[[#This Row],[Total Operating Expenses]]/FinancialAnalysis[[#This Row],[Revenue]] -> 0.18525291 | T181: =IF(FinancialAnalysis[[#This Row],[Operating Profit]]>0,"Profitable","Not Profitable") -> Profitable

Sheet Monthly Summary
A1: Month | B1: Actual Revenue | C1: Budget Revenue | D1: Revenue Variance | E1: Revenue Variance % | F1: Actual Operating Profit | G1: Budget Operating Profit | H1: Operating Profit Variance | I1: Operating Profit Variance %
A2: Jan | B2: =SUMIFS(FinancialData[Revenue],FinancialData[Month],MonthlySummary[[#This Row],[Month]]) -> 3482468 | C2: =_xlfn.XLOOKUP(MonthlySummary[[#This Row],[Month]],BudgetData[Month],BudgetData[Budget Revenue]) -> 3377297.5 | D2: =MonthlySummary[[#This Row],[Actual Revenue]]-MonthlySummary[[#This Row],[Budget Revenue]] -> 105170.53 | E2: =MonthlySummary[[#This Row],[Revenue Variance]]/MonthlySummary[[#This Row],[Budget Revenue]] -> 0.031140441 | F2: =SUMIFS(FinancialAnalysis[Operating Profit],FinancialAnalysis[Month],MonthlySummary[[#This Row],[Month]]) -> 580097.42 | G2: =_xlfn.XLOOKUP(MonthlySummary[[#This Row],[Month]],BudgetData[Month],BudgetData[Budget Operating Profit]) -> 701802.41 | H2: =MonthlySummary[[#This Row],[Actual Operating Profit]]-MonthlySummary[[#This Row],[Budget Operating Profit]] -> -121704.99 | I2: =MonthlySummary[[#This Row],[Operating Profit Variance]]/MonthlySummary[[#This Row],[Budget Operating Profit]] -> -0.17341774
A3: Feb | B3: =SUMIFS(FinancialData[Revenue],FinancialData[Month],MonthlySummary[[#This Row],[Month]]) -> 3832409 | C3: =_xlfn.XLOOKUP(MonthlySummary[[#This Row],[Month]],BudgetData[Month],BudgetData[Budget Revenue]) -> 3703256.8 | D3: =MonthlySummary[[#This Row],[Actual Revenue]]-MonthlySummary[[#This Row],[Budget Revenue]] -> 129152.18 | E3: =MonthlySummary[[#This Row],[Revenue Variance]]/MonthlySummary[[#This Row],[Budget Revenue]] -> 0.034875298 | F3: =SUMIFS(FinancialAnalysis[Operating Profit],FinancialAnalysis[Month],MonthlySummary[[#This Row],[Month]]) -> 580302.38 | G3: =_xlfn.XLOOKUP(MonthlySummary[[#This Row],[Month]],BudgetData[Month],BudgetData[Budget Operating Profit]) -> 758427 | H3: =MonthlySummary[[#This Row],[Actual Operating Profit]]-MonthlySummary[[#This Row],[Budget Operating Profit]] -> -178124.61 | I3: =MonthlySummary[[#This Row],[Operating Profit Variance]]/MonthlySummary[[#This Row],[Budget Operating Profit]] -> -0.23486059
A4: Mar | B4: =SUMIFS(FinancialData[Revenue],FinancialData[Month],MonthlySummary[[#This Row],[Month]]) -> 1976586 | C4: =_xlfn.XLOOKUP(MonthlySummary[[#This Row],[Month]],BudgetData[Month],BudgetData[Budget Revenue]) -> 1905033.6 | D4: =MonthlySummary[[#This Row],[Actual Revenue]]-MonthlySummary[[#This Row],[Budget Revenue]] -> 71552.413 | E4: =MonthlySummary[[#This Row],[Revenue Variance]]/MonthlySummary[[#This Row],[Budget Revenue]] -> 0.03755966 | F4: =SUMIFS(FinancialAnalysis[Operating Profit],FinancialAnalysis[Month],MonthlySummary[[#This Row],[Month]]) -> 286000.66 | G4: =_xlfn.XLOOKUP(MonthlySummary[[#This Row],[Month]],BudgetData[Month],BudgetData[Budget Operating Profit]) -> 358908.33 | H4: =MonthlySummary[[#This Row],[Actual Operating Profit]]-MonthlySummary[[#This Row],[Budget Operating Profit]] -> -72907.668 | I4: =MonthlySummary[[#This Row],[Operating Profit Variance]]/MonthlySummary[[#This Row],[Budget Operating Profit]] -> -0.2031373
A5: Apr | B5: =SUMIFS(FinancialData[Revenue],FinancialData[Month],MonthlySummary[[#This Row],[Month]]) -> 3158657 | C5: =_xlfn.XLOOKUP(MonthlySummary[[#This Row],[Month]],BudgetData[Month],BudgetData[Budget Revenue]) -> 3092009.3 | D5: =MonthlySummary[[#This Row],[Actual Revenue]]-MonthlySummary[[#This Row],[Budget Revenue]] -> 66647.663 | E5: =MonthlySummary[[#This Row],[Revenue Variance]]/MonthlySummary[[#This Row],[Budget Revenue]] -> 0.021554806 | F5: =SUMIFS(FinancialAnalysis[Operating Profit],FinancialAnalysis[Month],MonthlySummary[[#This Row],[Month]]) -> 563385.18 | G5: =_xlfn.XLOOKUP(MonthlySummary[[#This Row],[Month]],BudgetData[Month],BudgetData[Budget Operating Profit]) -> 758469.89 | H5: =MonthlySummary[[#This Row],[Actual Operating Profit]]-MonthlySummary[[#This Row],[Budget Operating Profit]] -> -195084.71 | I5: =MonthlySummary[[#This Row],[Operating Profit Variance]]/MonthlySummary[[#This Row],[Budget Operating Profit]] -> -0.25720824
A6: May | B6: =SUMIFS(FinancialData[Revenue],FinancialData[Month],MonthlySummary[[#This Row],[Month]]) -> 4117290 | C6: =_xlfn.XLOOKUP(MonthlySummary[[#This Row],[Month]],BudgetData[Month],BudgetData[Budget Revenue]) -> 3951363.2 | D6: =MonthlySummary[[#This Row],[Actual Revenue]]-MonthlySummary[[#This Row],[Budget Revenue]] -> 165926.79 | E6: =MonthlySummary[[#This Row],[Revenue Variance]]/MonthlySummary[[#This Row],[Budget Revenue]] -> 0.041992289 | F6: =SUMIFS(FinancialAnalysis[Operating Profit],FinancialAnalysis[Month],MonthlySummary[[#This Row],[Month]]) -> 895831.31 | G6: =_xlfn.XLOOKUP(MonthlySummary[[#This Row],[Month]],BudgetData[Month],BudgetData[Budget Operating Profit]) -> 810819.73 | H6: =MonthlySummary[[#This Row],[Actual Operating Profit]]-MonthlySummary[[#This Row],[Budget Operating Profit]] -> 85011.579 | I6: =MonthlySummary[[#This Row],[Operating Profit Variance]]/MonthlySummary[[#This Row],[Budget Operating Profit]] -> 0.10484646
A7: Jun | B7: =SUMIFS(FinancialData[Revenue],FinancialData[Month],MonthlySummary[[#This Row],[Month]]) -> 2318453 | C7: =_xlfn.XLOOKUP(MonthlySummary[[#This Row],[Month]],BudgetData[Month],BudgetData[Budget Revenue]) -> 2248435.7 | D7: =MonthlySummary[[#This Row],[Actual Revenue]]-MonthlySummary[[#This Row],[Budget Revenue]] -> 70017.281 | E7: =MonthlySummary[[#This Row],[Revenue Variance]]/MonthlySummary[[#This Row],[Budget Revenue]] -> 0.031140441 | F7: =SUMIFS(FinancialAnalysis[Operating Profit],FinancialAnalysis[Month],MonthlySummary[[#This Row],[Month]]) -> 310594.68 | G7: =_xlfn.XLOOKUP(MonthlySummary[[#This Row],[Month]],BudgetData[Month],BudgetData[Budget Operating Profit]) -> 292521.49 | H7: =MonthlySummary[[#This Row],[Actual Operating Profit]]-MonthlySummary[[#This Row],[Budget Operating Profit]] -> 18073.189 | I7: =MonthlySummary[[#This Row],[Operating Profit Variance]]/MonthlySummary[[#This Row],[Budget Operating Profit]] -> 0.061784141
A8: Jul | B8: =SUMIFS(FinancialData[Revenue],FinancialData[Month],MonthlySummary[[#This Row],[Month]]) -> 3583065 | C8: =_xlfn.XLOOKUP(MonthlySummary[[#This Row],[Month]],BudgetData[Month],BudgetData[Budget Revenue]) -> 3425051.8 | D8: =MonthlySummary[[#This Row],[Actual Revenue]]-MonthlySummary[[#This Row],[Budget Revenue]] -> 158013.17 | E8: =MonthlySummary[[#This Row],[Revenue Variance]]/MonthlySummary[[#This Row],[Budget Revenue]] -> 0.046134533 | F8: =SUMIFS(FinancialAnalysis[Operating Profit],FinancialAnalysis[Month],MonthlySummary[[#This Row],[Month]]) -> 513043.29 | G8: =_xlfn.XLOOKUP(MonthlySummary[[#This Row],[Month]],BudgetData[Month],BudgetData[Budget Operating Profit]) -> 568901.11 | H8: =MonthlySummary[[#This Row],[Actual Operating Profit]]-MonthlySummary[[#This Row],[Budget Operating Profit]] -> -55857.821 | I8: =MonthlySummary[[#This Row],[Operating Profit Variance]]/MonthlySummary[[#This Row],[Budget Operating Profit]] -> -0.098185467
A9: Aug | B9: =SUMIFS(FinancialData[Revenue],FinancialData[Month],MonthlySummary[[#This Row],[Month]]) -> 2893764 | C9: =_xlfn.XLOOKUP(MonthlySummary[[#This Row],[Month]],BudgetData[Month],BudgetData[Budget Revenue]) -> 2801452.9 | D9: =MonthlySummary[[#This Row],[Actual Revenue]]-MonthlySummary[[#This Row],[Budget Revenue]] -> 92311.072 | E9: =MonthlySummary[[#This Row],[Revenue Variance]]/MonthlySummary[[#This Row],[Budget Revenue]] -> 0.032951141 | F9: =SUMIFS(FinancialAnalysis[Operating Profit],FinancialAnalysis[Month],MonthlySummary[[#This Row],[Month]]) -> 494047.86 | G9: =_xlfn.XLOOKUP(MonthlySummary[[#This Row],[Month]],BudgetData[Month],BudgetData[Budget Operating Profit]) -> 545442.89 | H9: =MonthlySummary[[#This Row],[Actual Operating Profit]]-MonthlySummary[[#This Row],[Budget Operating Profit]] -> -51395.025 | I9: =MonthlySummary[[#This Row],[Operating Profit Variance]]/MonthlySummary[[#This Row],[Budget Operating Profit]] -> -0.094226227
A10: Sep | B10: =SUMIFS(FinancialData[Revenue],FinancialData[Month],MonthlySummary[[#This Row],[Month]]) -> 3786563 | C10: =_xlfn.XLOOKUP(MonthlySummary[[#This Row],[Month]],BudgetData[Month],BudgetData[Budget Revenue]) -> 3604429.3 | D10: =MonthlySummary[[#This Row],[Actual Revenue]]-MonthlySummary[[#This Row],[Budget Revenue]] -> 182133.68 | E10: =MonthlySummary[[#This Row],[Revenue Variance]]/MonthlySummary[[#This Row],[Budget Revenue]] -> 0.050530518 | F10: =SUMIFS(FinancialAnalysis[Operating Profit],FinancialAnalysis[Month],MonthlySummary[[#This Row],[Month]]) -> 684099.84 | G10: =_xlfn.XLOOKUP(MonthlySummary[[#This Row],[Month]],BudgetData[Month],BudgetData[Budget Operating Profit]) -> 857493.74 | H10: =MonthlySummary[[#This Row],[Actual Operating Profit]]-MonthlySummary[[#This Row],[Budget Operating Profit]] -> -173393.89 | I10: =MonthlySummary[[#This Row],[Operating Profit Variance]]/MonthlySummary[[#This Row],[Budget Operating Profit]] -> -0.2022101
A11: Oct | B11: =SUMIFS(FinancialData[Revenue],FinancialData[Month],MonthlySummary[[#This Row],[Month]]) -> 3395586 | C11: =_xlfn.XLOOKUP(MonthlySummary[[#This Row],[Month]],BudgetData[Month],BudgetData[Budget Revenue]) -> 3232258.3 | D11: =MonthlySummary[[#This Row],[Actual Revenue]]-MonthlySummary[[#This Row],[Budget Revenue]] -> 163327.69 | E11: =MonthlySummary[[#This Row],[Revenue Variance]]/MonthlySummary[[#This Row],[Budget Revenue]] -> 0.050530518 | F11: =SUMIFS(FinancialAnalysis[Operating Profit],FinancialAnalysis[Month],MonthlySummary[[#This Row],[Month]]) -> 543752.07 | G11: =_xlfn.XLOOKUP(MonthlySummary[[#This Row],[Month]],BudgetData[Month],BudgetData[Budget Operating Profit]) -> 561766.49 | H11: =MonthlySummary[[#This Row],[Actual Operating Profit]]-MonthlySummary[[#This Row],[Budget Operating Profit]] -> -18014.421 | I11: =MonthlySummary[[#This Row],[Operating Profit Variance]]/MonthlySummary[[#This Row],[Budget Operating Profit]] -> -0.032067454
A12: Nov | B12: =SUMIFS(FinancialData[Revenue],FinancialData[Month],MonthlySummary[[#This Row],[Month]]) -> 3230462 | C12: =_xlfn.XLOOKUP(MonthlySummary[[#This Row],[Month]],BudgetData[Month],BudgetData[Budget Revenue]) -> 3122564.6 | D12: =MonthlySummary[[#This Row],[Actual Revenue]]-MonthlySummary[[#This Row],[Budget Revenue]] -> 107897.43 | E12: =MonthlySummary[[#This Row],[Revenue Variance]]/MonthlySummary[[#This Row],[Budget Revenue]] -> 0.034554107 | F12: =SUMIFS(FinancialAnalysis[Operating Profit],FinancialAnalysis[Month],MonthlySummary[[#This Row],[Month]]) -> 560007.72 | G12: =_xlfn.XLOOKUP(MonthlySummary[[#This Row],[Month]],BudgetData[Month],BudgetData[Budget Operating Profit]) -> 632007.07 | H12: =MonthlySummary[[#This Row],[Actual Operating Profit]]-MonthlySummary[[#This Row],[Budget Operating Profit]] -> -71999.35 | I12: =MonthlySummary[[#This Row],[Operating Profit Variance]]/MonthlySummary[[#This Row],[Budget Operating Profit]] -> -0.11392175
A13: Dec | B13: =SUMIFS(FinancialData[Revenue],FinancialData[Month],MonthlySummary[[#This Row],[Month]]) -> 4148524 | C13: =_xlfn.XLOOKUP(MonthlySummary[[#This Row],[Month]],BudgetData[Month],BudgetData[Budget Revenue]) -> 4020334.6 | D13: =MonthlySummary[[#This Row],[Actual Revenue]]-MonthlySummary[[#This Row],[Budget Revenue]] -> 128189.39 | E13: =MonthlySummary[[#This Row],[Revenue Variance]]/MonthlySummary[[#This Row],[Budget Revenue]] -> 0.031885254 | F13: =SUMIFS(FinancialAnalysis[Operating Profit],FinancialAnalysis[Month],MonthlySummary[[#This Row],[Month]]) -> 878617.61 | G13: =_xlfn.XLOOKUP(MonthlySummary[[#This Row],[Month]],BudgetData[Month],BudgetData[Budget Operating Profit]) -> 975735.21 | H13: =MonthlySummary[[#This Row],[Actual Operating Profit]]-MonthlySummary[[#This Row],[Budget Operating Profit]] -> -97117.602 | I13: =MonthlySummary[[#This Row],[Operating Profit Variance]]/MonthlySummary[[#This Row],[Budget Operating Profit]] -> -0.099532743

Sheet Pivot Summary
A1: Revenue by Month
A2: Month | B2: Total Revenue
A3: Jan | B3: 3482468
A4: Feb | B4: 3832409
A5: Mar | B5: 1976586
A6: Apr | B6: 3158657
A7: May | B7: 4117290
A8: Jun | B8: 2318453
A9: Jul | B9: 3583065
A10: Aug | B10: 2893764
A11: Sep | B11: 3786563
A12: Oct | B12: 3395586
A13: Nov | B13: 3230462
A14: Dec | B14: 4148524
A15: Grand Total | B15: 39923827
A18: Revenue and Operating Profit by Sales Channel
A19: Sales Channel | B19: Total Revenue | C19: Total Operating Profit | F19: Sales Channel | G19: Total Revenue | H19: Total Operating Profit
A20: Online | B20: 12583215 | C20: 2110370.7 | F20: Online | G20: =GETPIVOTDATA("Total Revenue",$A$19,"Sales Channel","Online") -> 12583215 | H20: =GETPIVOTDATA("Total Operating Profit",$A$19,"Sales Channel","Online") -> 2110370.7
A21: Retail | B21: 7970715 | C21: 446414.31 | F21: Retail | G21: =GETPIVOTDATA("Total Revenue",$A$19,"Sales Channel","Retail") -> 7970715 | H21: =GETPIVOTDATA("Total Operating Profit",$A$19,"Sales Channel","Retail") -> 446414.31
A22: Wholesale | B22: 19369897 | C22: 4332995 | F22: Wholesale | G22: =GETPIVOTDATA("Total Revenue",$A$19,"Sales Channel","Wholesale") -> 19369897 | H22: =GETPIVOTDATA("Total Operating Profit",$A$19,"Sales Channel","Wholesale") -> 4332995
A23: Grand Total | B23: 39923827 | C23: 6889780
A26: Row Labels | B26: Sum of Revenue | C26: Sum of Gross Profit | D26: Gross Margin | F26: Row Labels | G26: Sum of Revenue | H26: Sum of Gross Profit | I26: Gross Margin
A27: Appliances | B27: 21379811 | C27: 6637077.8 | D27: =GETPIVOTDATA("Sum of Gross Profit",'Pivot Summary'!$A$26,"Department","Appliances")/GETPIVOTDATA("Sum of Revenue",'Pivot Summary'!$A$26,"Department","Appliances") -> 0.31043669 | F27: Appliances | G27: =B27 -> 21379811 | H27: =C27 -> 6637077.8 | I27: =D27 -> 0.31043669
A28: Furniture | B28: 9768660 | C28: 3372788.3 | D28: =GETPIVOTDATA("Sum of Gross Profit",$A$26,"Department","Furniture")/GETPIVOTDATA("Sum of Revenue",$A$26,"Department","Furniture") -> 0.34526622 | F28: Furniture | G28: =B28 -> 9768660 | H28: =C28 -> 3372788.3 | I28: =D28 -> 0.34526622
A29: Home Decor | B29: 2456933 | C29: 1140602.5 | D29: =GETPIVOTDATA("Sum of Gross Profit",$A$26,"Department","Home Decor")/GETPIVOTDATA("Sum of Revenue",$A$26,"Department","Home Decor") -> 0.46423832 | F29: Home Decor | G29: =B29 -> 2456933 | H29: =C29 -> 1140602.5 | I29: =D29 -> 0.46423832
A30: Kitchen | B30: 3364712 | C30: 1419656 | D30: =GETPIVOTDATA("Sum of Gross Profit",$A$26,"Department","Kitchen")/GETPIVOTDATA("Sum of Revenue",$A$26,"Department","Kitchen") -> 0.42192497 | F30: Kitchen | G30: =B30 -> 3364712 | H30: =C30 -> 1419656 | I30: =D30 -> 0.42192497
A31: Seasonal | B31: 2953711 | C31: 1171314.3 | D31: =GETPIVOTDATA("Sum of Gross Profit",$A$26,"Department","Seasonal")/GETPIVOTDATA("Sum of Revenue",$A$26,"Department","Seasonal") -> 0.39655684 | F31: Seasonal | G31: =B31 -> 2953711 | H31: =C31 -> 1171314.3 | I31: =D31 -> 0.39655684
A32: Grand Total | B32: 39923827 | C32: 13741439
A35: Operating Profit by Month and Sales Channel
A36: Total Operating Profit | B36: Sales Channel
A37: Month | B37: Online | C37: Retail | D37: Wholesale | E37: Grand Total
A38: Jan | B38: 254632.07 | C38: 1512.8498 | D38: 323952.5 | E38: 580097.42
A39: Feb | B39: 84410.103 | C39: 23922.958 | D39: 471969.32 | E39: 580302.38
A40: Mar | B40: 113741.01 | C40: -7377.0448 | D40: 179636.69 | E40: 286000.66
A41: Apr | B41: 222197.05 | C41: -5303.7844 | D41: 346491.92 | E41: 563385.18
A42: May | B42: 212521.44 | C42: 156276.12 | D42: 527033.75 | E42: 895831.31
A43: Jun | B43: 54658.692 | C43: -35900.425 | D43: 291836.41 | E43: 310594.68
A44: Jul | B44: 132078.92 | C44: 49643.145 | D44: 331321.23 | E44: 513043.29
A45: Aug | B45: 220303.48 | C45: 20695.62 | D45: 253048.76 | E45: 494047.86
A46: Sep | B46: 241033.53 | C46: 42250.275 | D46: 400816.04 | E46: 684099.84
...

Sheet Reconcilation
A1: Data Checks & Reconciliation
A2: This sheet is here to make sure the totals tie out and the data does not have obvious errors.
B5: Total Revenue
A6: Analysis Sheet | B6: =SUM(FinancialAnalysis[Revenue]) -> 39923827
A7: Pivot Summary Tables | B7: ='Pivot Summary'!B15 -> 39923827
A8: Difference | B8: =B6-B7 -> 0
A9: Status | B9: PASS
B12: Total Operating Profit
A13: Analysis Sheet | B13: =SUM(FinancialAnalysis[Operating Profit]) -> 6889780
A14: Pivot Summary Tables | B14: ='Pivot Summary'!C23 -> 6889780
A15: Difference | B15: =B13-B14 -> 0
A16: Status | B16: PASS
B19: Gross Profit
A20: Analysis Sheet | B20: =SUM(FinancialAnalysis[Gross Profit]) -> 13741439
A21: Pivot Summary Tables | B21: ='Pivot Summary'!C32 -> 13741439
A22: Difference | B22: =B20-B21 -> 0
A23: Status | B23: PASS
B26: Online Total Operating Profit | C26: Retail Total Operating Profit | D26: Wholesale Total Operating Profit
A27: Analysis Sheet | B27: =SUMIFS(FinancialAnalysis[Operating Profit],FinancialAnalysis[Sales Channel],"Online") -> 2110370.7 | C27: =SUMIFS(FinancialAnalysis[Operating Profit],FinancialAnalysis[Sales Channel],"Retail") -> 446414.31 | D27: =SUMIFS(FinancialAnalysis[Operating Profit],FinancialAnalysis[Sales Channel],"Wholesale") -> 4332995
A28: Pivot Summary Tables | B28: ='Pivot Summary'!B50 -> 2110370.7 | C28: ='Pivot Summary'!C50 -> 446414.31 | D28: ='Pivot Summary'!D50 -> 4332995
A29: Difference | B29: =B27-B28 -> 0 | C29: =C27-C28 -> 0 | D29: =D27-D28 -> 0
A30: Status | B30: PASS | C30: PASS | D30: PASS
B33: Total Marketing Expense | C33: Total Payroll Expense | D33: Total Rent Expense | E33: Total Other Expense
A34: Analysis Sheet | B34: =SUM(FinancialAnalysis[Marketing Expense]) -> 2257765 | C34: =SUM(FinancialAnalysis[Payroll Expense]) -> 1949337 | D34: =SUM(FinancialAnalysis[Allocated Rent Expense]) -> 1060752 | E34: =SUM(FinancialAnalysis[Other Expense]) -> 1583804.7
A35: Pivot Summary Tables | B35: ='Pivot Summary'!B67 -> 2257765 | C35: ='Pivot Summary'!C67 -> 1949337 | D35: ='Pivot Summary'!D67 -> 1060752 | E35: ='Pivot Summary'!E67 -> 1583804.7
A36: Difference | B36: =B34-B35 -> 0 | C36: =C34-C35 -> 0 | D36: =D34-D35 -> 0 | E36: =E34-E35 -> 0
A37: Status | B37: PASS | C37: PASS | D37: PASS | E37: PASS
B40: Budget Formula Check
A41: Total Budget Revenue | B41: =SUM(BudgetData[Budget Revenue]) -> 38483488
A42: Total Budget COGS | B42: =SUM(BudgetData[Budget COGS]) -> 21548669
A43: Total Budget Operating Expenses | B43: =SUM(BudgetData[Budget Operating Expenses]) -> 9112523.6
A44: Total Budget Operating Profit | B44: =SUM(BudgetData[Budget Operating Profit]) -> 7822295.3
A45: Difference | B45: =B41-B42-B43-B44 -> 0
A46: Status | B46: PASS
B49: Profit Status Check
A50: Analysis Sheet rows | B50: =ROWS(FinancialAnalysis[]) -> 180
A51: Profitable | B51: =COUNTIF(FinancialAnalysis[Profit Status],"Profitable") -> 141
A52: Not Profitable | B52: =COUNTIF(FinancialAnalysis[Profit Status],"Not Profitable") -> 39
A53: Invalid Category Count | B53: =B50-B51-B52 -> 0
A54: Status | B54: PASS
...
